Workbook
Name \a: '[1]処分損ﾒﾓ(月次)'!#REF!
Name \a: '[1]処分損ﾒﾓ(月次)'!#REF!
Name \a: '[1]処分損ﾒﾓ(月次)'!#REF!
Name _____sum1: #REF!
Name _____sum1: #REF!
Name ____ctb１: '[2]現行DB一覧2(CT)'!$A$2:$E$220
Name ____sum1: #REF!
Name ____sum1: #REF!
Name ___ctb１: '[2]現行DB一覧2(CT)'!$A$2:$E$220
Name ___sum1: #REF!
Name ___sum1: #REF!
Name ___sum1: #REF!
Name __ctb１: '[2]現行DB一覧2(CT)'!$A$2:$E$220
Name __sum1: #REF!
Name __sum1: #REF!
Name __sum1: #REF!
Name _1101ドキュメントGGG: #REF!,#REF!
Name _1101ドキュメントGGG: #REF!,#REF!
Name _1900_01_09: #REF!
Name _1900_01_09: #REF!
Name _1998_01_01: #REF!
Name _1998_01_01: #REF!
Name _1998_01_02: #REF!
Name _1998_01_02: #REF!
Name _1998_01_03: #REF!
Name _1998_01_03: #REF!
Name _1998_01_04: #REF!
Name _1998_01_04: #REF!
Name _1998_01_05: #REF!
Name _1998_01_05: #REF!
Name _1998_01_06: #REF!
Name _1998_01_06: #REF!
Name _1998_01_07: #REF!
Name _1998_01_07: #REF!
Name _1998_01_08: #REF!
Name _1998_01_08: #REF!
Name _1998_01_09: #REF!
Name _1998_01_09: #REF!
Name _1998_01_10: #REF!
Name _1998_01_10: #REF!
Name _1998_01_11: #REF!
Name _1998_01_11: #REF!
Name _1998_01_12: #REF!
Name _1998_01_12: #REF!
Name _1998_01_13: #REF!
Name _1998_01_13: #REF!
Name _1998_01_14: #REF!
Name _1998_01_14: #REF!
Name _1998_01_15: #REF!
Name _1998_01_15: #REF!
Name _1998_01_16: #REF!
Name _1998_01_16: #REF!
Name _1998_01_17: #REF!
Name _1998_01_17: #REF!
Name _1998_01_18: #REF!
Name _1998_01_18: #REF!
Name _1998_01_19: #REF!
Name _1998_01_19: #REF!
Name _1998_01_20: #REF!
Name _1998_01_20: #REF!

Sheet シート説明
A1: ● 目的
B2: 協力会社様からご提示いただいた見積明細に見積根拠を記載していただき、実施すべき内容の過不足、
B3: 認識齟齬がないかをシス部担当者で確認できるように本フォーマットを公開します。
B4: 10人月以上の案件は本見積シートを必ずご利用ください
B6: ※ 本シートは詳細設計以降の見積にご利用ください。
A8: ● 利用方法 | E8: ※ 詳細設計 ～ システムテスト 本番移行シートの記載方法
B9: シート名 | C9: 記載方法
B10: 見積総額 | C10: 本シートのフォーマットで作成ください。 I列の単価、ランクは各社様で記載ください。 | E10: 機能名（C列） 機能概要（D列） | F10: プロジェクトに応じて行を追加・削除可能 ※ システムテスト以降についても同様です。
B11: 前提条件 | C11: フリーフォーマット | E11: ボリューム （H列） | F11: 画面数、参照、更新テーブル数、利用コンポ、バッチ数を記載
B12: システム構成図 | C12: フリーフォーマット | E12: 工数説明（難易度説明） （I列） | F12: Sランク・最下層のランク： 工数の根拠がわかるよう説明を記載ください。 Sランク、最下位ランク以外： そのランクを選んだ根拠を記載ください。 調整工数の根拠も必ず記載ください。
B13: 詳細設計 ～ システムテスト 本番移行 | C13: 本シートのフォーマットで作成ください。 サンプルに示したくらいの粒度で記載ください。 | E13: 標準作業工数 （J～M列） | F13: Sランク・最下層のランク： 直接見積工数を記載ください。 Sランク、最下位ランク以外： 「難易度別標準工数」シートで定義した工数を記載ください。
B14: 難易度別標準工数 | C14: 本シートのフォーマットで作成ください。 プロジェクトごとの特性に応じた、難易度別テーブルを作成 ・D列～G列のフェーズ追加（列追加）は不可です。 ※ 詳細設計、実装、単体テスト、結合テスト ・ランクを追加は可能です。 ※ デフォルトはS～Dの5ランクで定義 ・Sランクと、最下層のランクは個別算出です。 ※ 個別算出分は機能別に工数見積 | E14: 調整工数 （N～Q列） | F14: 標準工数から過不足がある場合は、調整工数を記載ください。 ※ Sランクと、最下層のランクは個別算出（機能別に工数見積）に なりますので、記載不要です。
F15: 調整工数 利用例： それぞれの機能別だと、結合テストが多すぎるのである機能でマイナス調整。 ※ 詳細設計～システムテスト 本番移行シート １．画面のNo.12のパターン） 再利用できる機能がある場合。 ※ 詳細設計～システムテスト 本番移行シート １．画面のNo.1のパターン） 追加要件があるため、工数が足りない場合 ※ 詳細設計～システムテスト 本番移行シート １．画面のNo.10のパターン）
B16: 体制 | C16: フリーフォーマット | E16: 見積工数 （R～U列） | F16: 自動計算されます。
B17: 成果物 | C17: フリーフォーマット
B18: スケジュール | C18: フリーフォーマット

Sheet 見積総額
B2: Sample Project
H3: 最終更新：YYYY/MM/DD
B4: ① Sample approach 1
B5: 項目 | C5: 工数（人日） | D5: 工数（人月） | E5: ランク | F5: 工数（人月） ランク別 | G5: 単価（円） | H5: 金額（円）
B6: プロジェクト管理 | C6: ='詳細設計～システムテスト 本番移行'!U68 -> 14 | D6: =C6/20 -> 0.7 | E6: PL | F6: =D6 -> 0.7 | H6: =F6*G6 -> 0
B7: 詳細設計 | C7: ='詳細設計～システムテスト 本番移行'!U62 -> 17 | D7: =C7/20 -> 0.85 | E7: SE | F7: =D7 -> 0.85 | H7: =F7*G7 -> 0
B8: 実装 | C8: ='詳細設計～システムテスト 本番移行'!U63 -> 12 | D8: =C8/20 -> 0.6 | E8: SE | F8: =D8-F9 -> 0.6 | H8: =F8*G8 -> 0
E9: PG | F9: 0 | H9: =F9*G9 -> 0
B10: 単体テスト | C10: ='詳細設計～システムテスト 本番移行'!U64 -> 26 | D10: =C10/20 -> 1.3 | E10: SE | F10: =D10 -> 1.3 | H10: =F10*G10 -> 0
B11: 結合テスト | C11: ='詳細設計～システムテスト 本番移行'!U65 -> 15 | D11: =C11/20 -> 0.75 | E11: SE | F11: =D11 -> 0.75 | H11: =F11*G11 -> 0
B12: システムテスト・ユーザテスト | C12: ='詳細設計～システムテスト 本番移行'!U66 -> 1.5 | D12: =C12/20 -> 0.075 | E12: SE | F12: =D12-F13 -> 0.075 | H12: =F12*G12 -> 0
E13: PG | F13: 0 | H13: =F13*G13 -> 0
B14: 本番化作業・初期流動 | C14: ='詳細設計～システムテスト 本番移行'!U67 -> 3 | D14: =C14/20 -> 0.15 | E14: SE | F14: =D14 -> 0.15 | H14: =F14*G14 -> 0
B15: 合計 | D15: =SUM(D6:D14) -> 4.425 | H15: =SUM(H6:H14) -> 0
B18: ② Sample approach 2
B19: 項目 | C19: 工数（人日） | D19: 工数（人月） | E19: ランク | F19: 工数（人月） ランク別 | G19: 単価（円） | H19: 金額（円）
B20: プロジェクト管理 | C20: ='詳細設計～システムテスト 本番移行_2'!U68 -> 6.2 | D20: =C20/20 -> 0.31 | E20: PL | F20: =D20 -> 0.31 | H20: =F20*G20 -> 0
B21: 詳細設計 | C21: ='詳細設計～システムテスト 本番移行_2'!U63 -> 4.5 | D21: =C21/20 -> 0.225 | E21: SE | F21: =D21 -> 0.225 | H21: =F21*G21 -> 0
B22: 実装 | C22: ='詳細設計～システムテスト 本番移行_2'!U63 -> 4.5 | D22: =C22/20 -> 0.225 | E22: SE | F22: =D22-F23 -> 0.225 | H22: =F22*G22 -> 0
E23: PG | F23: 0 | H23: =F23*G23 -> 0
B24: 単体テスト | C24: ='詳細設計～システムテスト 本番移行_2'!U64 -> 11.5 | D24: =C24/20 -> 0.575 | E24: SE | F24: =D24 -> 0.575 | H24: =F24*G24 -> 0
B25: 結合テスト | C25: ='詳細設計～システムテスト 本番移行_2'!U65 -> 7 | D25: =C25/20 -> 0.35 | E25: SE | F25: =D25 -> 0.35 | H25: =F25*G25 -> 0
B26: システムテスト・ユーザテスト | C26: ='詳細設計～システムテスト 本番移行_2'!U66 -> 0 | D26: =C26/20 -> 0 | E26: SE | F26: =D26-F27 -> 0 | H26: =F26*G26 -> 0
E27: PG | F27: 0 | H27: =F27*G27 -> 0
B28: 本番化作業・初期流動 | C28: ='詳細設計～システムテスト 本番移行_2'!U67 -> 3 | D28: =C28/20 -> 0.15 | E28: SE | F28: =D28 -> 0.15 | H28: =F28*G28 -> 0
B29: 合計 | D29: =SUM(D20:D28) -> 1.835 | H29: =SUM(H20:H28) -> 0

Sheet 対応方針
B2: =見積総額!B2&" " & RIGHT(CELL("filename", A1), LEN(CELL("filename", A1))-FIND("]",CELL("filename", A1))) -> Sample Project 対応方針

Sheet 前提条件
B2: =見積総額!B2&" " & RIGHT(CELL("filename", A1), LEN(CELL("filename", A1))-FIND("]",CELL("filename", A1))) -> Sample Project 前提条件
D3: 最終更新：6/16/2026（火）
B4: No. | C4: 分類 | D4: 内容

Sheet システム構成図
B2: =見積総額!B2&" " & RIGHT(CELL("filename", B1), LEN(CELL("filename", B1))-FIND("]",CELL("filename", B1))) -> Sample Project システム構成図

Sheet 詳細設計～システムテスト 本番移行
B2: =見積総額!B2&" " & RIGHT(CELL("filename", A1), LEN(CELL("filename", A1))-FIND("]",CELL("filename", A1))) -> Sample Project 詳細設計～システムテスト 本番移行
V3: 最終更新：2/27/2026（金）
V4: （人日）
B5: No | C5: 機能名 | D5: 機能概要 | E5: 要件（ユースケース） | F5: 難易度 | G5: 新規/改定 | H5: 見積根拠 | J5: 標準作業工数（人日） | N5: 調整工数（人日） | R5: 見積工数（人日） | V5: 備考
H6: ボリューム | I6: 工数説明（難易度説明） ※ 難易度別標準工数シートから工数が外れる場合は、その根拠を記載。 | J6: 難易度別標準工数 | N6: 再利用率等考慮
H7: ※ 画面数・DB数・ステップ数 等 | J7: 詳細設計 | K7: 実装 | L7: 単体テスト | M7: 結合テスト | N7: 詳細設計 | O7: 実装 | P7: 単体テスト | Q7: 結合テスト | R7: 詳細設計 | S7: 実装 | T7: 単体テスト | U7: 結合テスト
C8: 1.処理・画面
B9: 1 | C9: Sample Function 1 | D9: Sample overview 1 | F9: A | H9: Sample estimate basis 1 | I9: Sample work explanation 1 | J9: =VLOOKUP($F9,難易度別標準工数!$B$7:$G$10,3,FALSE) -> 5 | K9: =VLOOKUP($F9,難易度別標準工数!$B$7:$G$10,4,FALSE) -> 3 | L9: =VLOOKUP($F9,難易度別標準工数!$B$7:$G$10,5,FALSE) -> 7 | M9: =VLOOKUP($F9,難易度別標準工数!$B$7:$G$10,6,FALSE) -> 5 | R9: =J9+N9 -> 5 | S9: =K9+O9 -> 3 | T9: =L9+P9 -> 7 | U9: =M9+Q9 -> 5
B10: 2 | C10: Sample Function 2 | D10: Sample overview 2 | F10: B | H10: Sample estimate basis 2 | I10: Sample work explanation 2 | J10: =VLOOKUP($F10,難易度別標準工数!$B$7:$G$10,3,FALSE) -> 3 | K10: =VLOOKUP($F10,難易度別標準工数!$B$7:$G$10,4,FALSE) -> 1.5 | L10: =VLOOKUP($F10,難易度別標準工数!$B$7:$G$10,5,FALSE) -> 4.5 | M10: =VLOOKUP($F10,難易度別標準工数!$B$7:$G$10,6,FALSE) -> 3 | Q10: -1 | R10: =J10+N10 -> 3 | S10: =K10+O10 -> 1.5 | T10: =L10+P10 -> 4.5 | U10: =M10+Q10 -> 2
B11: 3 | C11: Sample Function 3 | D11: Sample overview 3 | F11: C | H11: Sample estimate basis 3 | I11: Sample work explanation 3 | J11: =VLOOKUP($F11,難易度別標準工数!$B$7:$G$10,3,FALSE) -> 1 | K11: =VLOOKUP($F11,難易度別標準工数!$B$7:$G$10,4,FALSE) -> 1 | L11: =VLOOKUP($F11,難易度別標準工数!$B$7:$G$10,5,FALSE) -> 2 | M11: =VLOOKUP($F11,難易度別標準工数!$B$7:$G$10,6,FALSE) -> 1 | P11: 1 | R11: =J11+N11 -> 1 | S11: =K11+O11 -> 1 | T11: =L11+P11 -> 3 | U11: =M11+Q11 -> 1
B12: 4 | C12: Sample Function 4 | D12: Sample overview 4 | F12: A | H12: Sample estimate basis 4 | I12: Sample work explanation 4 | J12: =VLOOKUP($F12,難易度別標準工数!$B$7:$G$10,3,FALSE) -> 5 | K12: =VLOOKUP($F12,難易度別標準工数!$B$7:$G$10,4,FALSE) -> 3 | L12: =VLOOKUP($F12,難易度別標準工数!$B$7:$G$10,5,FALSE) -> 7 | M12: =VLOOKUP($F12,難易度別標準工数!$B$7:$G$10,6,FALSE) -> 5 | R12: =J12+N12 -> 5 | S12: =K12+O12 -> 3 | T12: =L12+P12 -> 7 | U12: =M12+Q12 -> 5
B13: 5 | C13: Sample Function 5 | D13: Sample overview 5 | F13: B | H13: Sample estimate basis 5 | I13: Sample work explanation 5 | J13: =VLOOKUP($F13,難易度別標準工数!$B$7:$G$10,3,FALSE) -> 3 | K13: =VLOOKUP($F13,難易度別標準工数!$B$7:$G$10,4,FALSE) -> 1.5 | L13: =VLOOKUP($F13,難易度別標準工数!$B$7:$G$10,5,FALSE) -> 4.5 | M13: =VLOOKUP($F13,難易度別標準工数!$B$7:$G$10,6,FALSE) -> 3 | Q13: -1 | R13: =J13+N13 -> 3 | S13: =K13+O13 -> 1.5 | T13: =L13+P13 -> 4.5 | U13: =M13+Q13 -> 2
B17: 1 | R17: =J17+N17 -> 0 | S17: =K17+O17 -> 0 | T17: =L17+P17 -> 0 | U17: =M17+Q17 -> 0
B18: 2 | R18: =J18+N18 -> 0 | S18: =K18+O18 -> 0 | T18: =L18+P18 -> 0 | U18: =M18+Q18 -> 0
B19: 3
B20: 4
B21: 5
B22: 6
C23: 3.全般
B24: =B16+1 -> 1 | C24: Sample Function 6 | D24: Sample overview 6 | K24: 2 | P24: 1 | R24: =J24+N24 -> 0 | S24: =K24+N24 -> 2 | T24: =L24+O24 -> 0 | U24: =M24+Q24 -> 0
B25: 2 | R25: =J25+N25 -> 0 | S25: =K25+O25 -> 0 | T25: =L25+O25 -> 0 | U25: =M25+Q25 -> 0
I26: 小計（工程別） | J26: =SUM(J8:J25) -> 17 | K26: =SUM(K8:K25) -> 12 | L26: =SUM(L8:L25) -> 25 | M26: =SUM(M8:M25) -> 17 | N26: =SUM(N8:N25) -> 0 | O26: =SUM(O8:O25) -> 0 | P26: =SUM(P8:P25) -> 2 | Q26: =SUM(Q8:Q25) -> -2 | ... U26: =SUM(U8:U25) -> 15
B28: No | C28: 機能名 | D28: 機能概要 | E28: 要件（ユースケース） | F28: 難易度 | G28: 新規/改定 | H28: 見積根拠 | J28: 標準作業工数（人日） | N28: 調整工数（人日） | R28: 見積工数（人日） | V28: 備考
H29: ボリューム | I29: 工数説明 ※ 難易度別標準工数シートから工数が外れる場合は、必ず根拠を記載
H30: ※ 画面数・DB数・ステップ数 等 | R30: 工数
C31: 1.機能外テスト
B32: 1 | C32: Sample Function 7 | H32: Sample estimate basis 7 | R32: =2/8 -> 0.25
B33: 2 | H33: 対応10H | R33: =10/8 -> 1.25
B34: 3
B35: 4
B36: 5
B37: 6
B38: 7
B39: 8
C40: ２.ユーザテスト
B41: 1
B42: 2
B43: 3
C44: ３.移行
B45: 1 | C45: Sample Function 8 | H45: Sample estimate basis 8 | Q45: -1 | R45: 3
...

Sheet 詳細設計～システムテスト 本番移行_2
B2: =見積総額!B2&" " & RIGHT(CELL("filename", A1), LEN(CELL("filename", A1))-FIND("]",CELL("filename", A1))) -> Sample Project 詳細設計～システムテスト 本番移行_2
V3: 最終更新：2/27/2026（金）
V4: （人日）
B5: No | C5: 機能名 | D5: 機能概要 | E5: 要件（ユースケース） | F5: 難易度 | G5: 新規/改定 | H5: 見積根拠 | J5: 標準作業工数（人日） | N5: 調整工数（人日） | R5: 見積工数（人日） | V5: 備考
H6: ボリューム | I6: 工数説明（難易度説明） ※ 難易度別標準工数シートから工数が外れる場合は、その根拠を記載。 | J6: 難易度別標準工数 | N6: 再利用率等考慮
H7: ※ 画面数・DB数・ステップ数 等 | J7: 詳細設計 | K7: 実装 | L7: 単体テスト | M7: 結合テスト | N7: 詳細設計 | O7: 実装 | P7: 単体テスト | Q7: 結合テスト | R7: 詳細設計 | S7: 実装 | T7: 単体テスト | U7: 結合テスト
C8: 1.処理・画面
B9: 1 | C9: Sample Function 1 | D9: Sample overview 1 | F9: A | H9: Sample estimate basis 1 | J9: =VLOOKUP($F9,難易度別標準工数!$B$7:$G$10,3,FALSE) -> 5 | K9: =VLOOKUP($F9,難易度別標準工数!$B$7:$G$10,4,FALSE) -> 3 | L9: =VLOOKUP($F9,難易度別標準工数!$B$7:$G$10,5,FALSE) -> 7 | M9: =VLOOKUP($F9,難易度別標準工数!$B$7:$G$10,6,FALSE) -> 5 | R9: =J9+N9 -> 5 | S9: =K9+O9 -> 3 | T9: =L9+P9 -> 7 | U9: =M9+Q9 -> 5
B10: 2 | C10: Sample Function 2 | D10: Sample overview 2 | F10: B | H10: Sample estimate basis 2 | J10: =VLOOKUP($F10,難易度別標準工数!$B$7:$G$10,3,FALSE) -> 3 | K10: =VLOOKUP($F10,難易度別標準工数!$B$7:$G$10,4,FALSE) -> 1.5 | L10: =VLOOKUP($F10,難易度別標準工数!$B$7:$G$10,5,FALSE) -> 4.5 | M10: =VLOOKUP($F10,難易度別標準工数!$B$7:$G$10,6,FALSE) -> 3 | Q10: -1 | R10: =J10+N10 -> 3 | S10: =K10+O10 -> 1.5 | T10: =L10+P10 -> 4.5 | U10: =M10+Q10 -> 2
B17: 1 | R17: =J17+N17 -> 0 | S17: =K17+O17 -> 0 | T17: =L17+P17 -> 0 | U17: =M17+Q17 -> 0
B18: 2 | R18: =J18+N18 -> 0 | S18: =K18+O18 -> 0 | T18: =L18+P18 -> 0 | U18: =M18+Q18 -> 0
B19: 3
B20: 4
B21: 5
B22: 6
C23: 3.全般
B24: =B16+1 -> 1 | R24: =J24+N24 -> 0 | S24: =K24+N24 -> 0 | T24: =L24+O24 -> 0 | U24: =M24+Q24 -> 0
B25: 2 | R25: =J25+N25 -> 0 | S25: =K25+N25 -> 0 | T25: =L25+O25 -> 0 | U25: =M25+Q25 -> 0
I26: 小計（工程別） | J26: =SUM(J8:J25) -> 8 | K26: =SUM(K8:K25) -> 4.5 | L26: =SUM(L8:L25) -> 11.5 | M26: =SUM(M8:M25) -> 8 | N26: =SUM(N8:N25) -> 0 | O26: =SUM(O8:O25) -> 0 | P26: =SUM(P8:P25) -> 0 | Q26: =SUM(Q8:Q25) -> -1 | ... U26: =SUM(U8:U25) -> 7
B28: No | C28: 機能名 | D28: 機能概要 | E28: 要件（ユースケース） | F28: 難易度 | G28: 新規/改定 | H28: 見積根拠 | J28: 標準作業工数（人日） | N28: 調整工数（人日） | R28: 見積工数（人日） | V28: 備考
H29: ボリューム | I29: 工数説明 ※ 難易度別標準工数シートから工数が外れる場合は、必ず根拠を記載
H30: ※ 画面数・DB数・ステップ数 等 | R30: 工数
C31: 1.機能外テスト
B32: 1
B33: 2
B34: 3
B35: 4
B36: 5
B37: 6
B38: 7
B39: 8
C40: ２.ユーザテスト
B41: 1
B42: 2
B43: 3
C44: ３.移行
B45: 1 | C45: Sample Function 3 | H45: Sample estimate basis 3 | P45: 1 | R45: 3
B46: 2
B47: 2
B48: 3
...

Sheet 難易度別標準工数
B2: =見積総額!B2&" " & RIGHT(CELL("filename", A1), LEN(CELL("filename", A1))-FIND("]",CELL("filename", A1))) -> Sample Project 難易度別標準工数
H3: 最終更新：3/19/2026（Thu）
H4: （人日）
B5: 難易度 | C5: 説明 | D5: 詳細設計 | E5: 実装 | F5: 単体テスト | G5: 結合テスト | H5: 備考
B6: S | C6: 難易度 高の工数では収まらない特例の機能 ※ 工数の根拠を含め内訳を工数説明に記載 | D6: 個別算出
B7: A | C7: 複雑な処理を一部含み、一般的な機能より工数がかかる ※ 難易度の選択理由を記載 | D7: 5 | E7: 3 | F7: 7 | G7: 5
B8: B | C8: 複雑な機能もなく、簡単な一覧検索や検索・登録機能 ※ 難易度の選択理由を記載 | D8: 3 | E8: 1.5 | F8: 4.5 | G8: 3
B9: C | C9: 単純な画面、バッチ機能 ※ 難易度の選択理由を記載 | D9: 1 | E9: 1 | F9: 2 | G9: 1
B10: D | C10: Cで定義した工数よりも少ない工数で開発できる機能 ※ 工数の根拠を含め内訳を工数説明に記載
B11: ※ 難易度説明のための説明はすべて記載ください。
B12: ※ 工数を難易度別工数に合わせる必要はありませんが、外れる場合は根拠をご説明ください。
B13: ※ 難易度別工数（目安）を記載してから見積シートに工数を記載ください。
B14: ※ 新規/改定別に標準工数表を分けて記載いただいても問題ありません。
B15: ただし、画面、バッチ等、機能別に標準工数表を分けて作成しないようにしてください。

Sheet 体制
B2: =見積総額!B2&" " & RIGHT(CELL("filename", A1), LEN(CELL("filename", A1))-FIND("]",CELL("filename", A1))) -> Sample Project 体制
K3: 最終更新：6/15/2026（月）

Sheet 成果物
C2: =見積総額!B2&" " & RIGHT(CELL("filename", A1), LEN(CELL("filename", A1))-FIND("]",CELL("filename", A1))) -> Sample Project 成果物
G3: 最終更新：2/27/2026（金）
C4: NO | D4: 分類 | E4: 成果物 | F4: 説明 | G4: 納品対象
A5: 詳細設計 | C5: =ROW()-4 -> 1 | D5: 詳細設計 | E5: 画面処理仕様書 | F5: ■画面に関する仕様を詳細に記述したドキュメント | G5: 要
C6: =ROW()-4 -> 2 | E6: バッチ処理仕様書 | F6: ■バッチに関する仕様を詳細に記述したドキュメント | G6: 不要
C7: =ROW()-4 -> 3 | E7: 帳票仕様書 | F7: ■システムから発信されるメールに関する仕様を詳細に記述したドキュメント | G7: 不要
A8: システムテスト | C8: =ROW()-4 -> 4 | E8: 移行・初期流動計画書 | F8: ■既存システムから移行する際の移行設計書 ■以下の事項ついて記述する ・移行データ一覧 ・データ移行方式（フロー等） ・作業手順書 ■本番移行する資源の一覧とその実施手順を記述したドキュメント ■サービスイン後の初期流動管理の計画書 ■初期流動時のチェックポイントとチェック結果を記述する ■エビデンスも記載する | G8: 不要
A9: 本番化 | C9: =ROW()-4 -> 5 | E9: メール一覧・仕様書 | F9: ■システムから発信されるメールに関する仕様を詳細に記述したドキュメント ・メール一覧 ・メール宛先 ・メール内容（タイトル・本文） ・送信タイミング | G9: 不要
A10: プロジェクト管理 | C10: =ROW()-4 -> 6 | E10: ファイル・連携フォーマット一覧 | F10: ■ファイル、システム間連携データのフォーマットに関する仕様を詳細に作成 ・レイアウト定義 ・項目定義 ※ JSON、CSV、XMLなどのフォーマット定義 | G10: 不要
C11: =ROW()-4 -> 7 | E11: テーブルレイアウト | F11: ■コンセプト時のDBレイアウトに追加データ項目等があれば、更新する | G11: 不要
C12: =ROW()-4 -> 8 | E12: ネットフロー | F12: ■バッチ処理のネットフロー | G12: 不要
C13: =ROW()-4 -> 9 | E13: ジョブフロー | F13: ■ジョブネットに属するジョブのジョブフロー | G13: 不要
C14: =ROW()-4 -> 10 | E14: 詳細設計チェックリスト (単体テストチェックリスト) | F14: ■詳細設計を行っていくうえで、「ルールでは決められていないが、各プロジェクトで決定しなければいけないこと」のチェックリストです。 ■システム別設計・実装規約定義書」のチェックリストとして使用ください。また、単体テストのテストケースチェックにも使用ください。 | G14: 要
C15: =ROW()-4 -> 11 | E15: ユーザーマニュアル | F15: ■システムのユーザーマニュアル ■システム利用者に分かりやすい形式で作成すること | G15: 不要
C16: =ROW()-4 -> 12 | D16: 実装・単体テスト | E16: PGソース・実行モジュール | F16: ■設計書をもとに実装するプログラムソースと実行モジュール | G16: 要
C17: =ROW()-4 -> 13 | E17: 単体テスト計画書 | F17: ■単体テスト開始前に、目的・範囲／実施概要／テスト運用／開始・完了条件／スケジュール／体制を、計画するためのドキュメント | G17: 不要
C18: =ROW()-4 -> 14 | E18: 単体テスト仕様書 | F18: ■単体テストのテストパターンとテスト結果を記述する ■エビデンスも付与する | G18: 要
C19: =ROW()-4 -> 15 | E19: セキュリティ対策チェックリスト （詳細設計後） | F19: ■結合テストの前にセキュリティ部門 部長の承認必須 ■サービス確認会議にて結果報告必須 ■Webアプリ詳細設計を行っていくうえで、アプリ脆弱性を防ぐためのチェックリストです。 | G19: 不要
C20: =ROW()-4 -> 16 | D20: 結合テスト | E20: 結合テスト計画書 | F20: ■結合テスト開始前に、目的・範囲／実施概要／テスト運用／開始・完了条件／スケジュール／体制を、計画するためのドキュメント | G20: 不要
C21: =ROW()-4 -> 17 | E21: 結合テスト仕様書 | F21: ■結合テストのテストパターンとテスト結果を記述する ■エビデンスも付与する | G21: 要
C22: =ROW()-4 -> 18 | E22: 結合テストチェックリスト | F22: ■結合テストでモレがちな項目をチェックリストにしたドキュメント | G22: 不要
C23: =ROW()-4 -> 19 | D23: システムテスト | E23: システムテスト計画書 | F23: ■システムテスト開始前に、目的・範囲／実施概要／テスト運用／開始・完了条件／スケジュール／体制を、計画するためのドキュメント | G23: 不要
C24: =ROW()-4 -> 20 | E24: システムテスト仕様書 | F24: ■システムテストのテストパターンとテスト結果を記述する ■エビデンスも付与する | G24: 不要
C25: =ROW()-4 -> 21 | E25: 機能外テスト仕様書 | F25: ■機能外テストのテストパターンとテスト結果を記述する ■エビデンスも付与する | G25: 不要
C26: =ROW()-4 -> 22 | D26: 移行（本番化） | E26: パララン計画書 | F26: ■パラレルラン開始前に、目的・範囲／実施概要／確認事項／リスク回避／スケジュール／体制を、計画するためのドキュメント | G26: 不要
C27: =ROW()-4 -> 23 | E27: 運用テスト仕様書 | F27: ■運用テストのテストパターンとテスト結果を記述する ■エビテンスも付与 | G27: 不要
C28: =ROW()-4 -> 24 | E28: 本番機移行チェックリスト | F28: ■アプリケーションの本番移行に伴うトラブルの未然防止や、移行後の稼動確認漏れを防止することを目的としたチェックリスト ■本番機移行前後に最低限必要なチェック項目が記載されている ■各アプリケーションで必要な項目を追加して利用すること | G28: 不要
C29: =ROW()-4 -> 25 | E29: セキュリティ対策チェックリスト （テスト後） | F29: ■セキュリティに関するチェックリスト ■サービスイン確認会議前にチェックし、セキュリティ部門 課長への提出必須 ■サービスイン確認会議で、チェック済みである旨を報告すること | G29: 不要
C30: =ROW()-4 -> 26 | E30: トラブル撲滅チェックリスト (2回目） | F30: ■大規模トラブルの未然防止を目的としたチェックリスト ■本番機で稼動させる前に確かに問題がないことを確認し、品質関連部門（PMO）に提出すること | G30: 不要
C31: =ROW()-4 -> 27 | E31: 変更管理資料・本番化手順書 | F31: ■本番化時に使用する変更管理資料・本番化手順書 | G31: 不要
C32: =ROW()-4 -> 28 | D32: 運用引継ぎ | E32: 引継ぎスケジュール | F32: ■システム運用引継ぎの項目と各スケジュールを明示する | G32: 不要
C33: =ROW()-4 -> 29 | E33: 定例・臨時作業一覧 | F33: ■引き継ぎ対象システムの次の定義をする ■システム対象／システム構成／インフラ構成／サーバ情報／機能一覧 ■アプリケーションの日々の運用に必要な監視内容を定義する ■マスタ登録、データ抽出等、定例作業を定義する
C34: =ROW()-4 -> 30 | D34: プロジェクト管理 | E34: 詳細スケジュール | F34: ■開発におけるWBS | G34: 要
C35: =ROW()-4 -> 31 | D35: プロジェクト管理 | E35: 課題管理表 | F35: ■開発に関する仕様・課題管理表 | G35: 要
C36: =ROW()-4 -> 32 | E36: 不具合管理表 | F36: ■単体・結合・システム・統合テスト時に発生した不具合管理表 | G36: 要
C37: =ROW()-4 -> 33 | E37: 変更一覧 | F37: ■詳細設計以降の一括契約締結後、仕様変更が発生した場合、このドキュメントで、変更要求／実施判断ステータス／工数を管理する | G37: 要

Sheet スケジュール
A2: =見積総額!B2&" " & RIGHT(CELL("filename", A1), LEN(CELL("filename", A1))-FIND("]",CELL("filename", A1))) -> Sample Project スケジュール
L3: 最終更新：20XX/XX/XX（〇〇）
